<?xml version="1.0" ?>
<robot name="scene" version="1.0">
  <link name="world"/>
  <link name="manipulator_flange"/>
  <link name="base_link">
    <inertial>
      <origin xyz="-3.77960552443097e-05 6.79413834922362e-05 0.0272675975957773" rpy="0.0 0.0 0.0"/>
      <mass value="0.155112526591278"/>
      <inertia ixx="7.60347373757683e-05" ixy="1.31363578468253e-07" ixz="1.65990805634842e-07" iyy="7.64176389864096e-05" iyz="-2.98381448658278e-07" izz="6.94914158355665e-05"/>
    </inertial>
    <visual>
      <origin xyz="0.0 0.0 0.0" rpy="0.0 0.0 0.0"/>
      <geometry>
        <mesh filename="/home/homa/IsaacStressor/assets/arx5_description/meshes/base_arm.dae"/>
      </geometry>
      <material name="black">
        <color rgba="0.05 0.05 0.05 0.98"/>
      </material>
    </visual>
    <collision>
      <origin xyz="0.0 0.0 0.0" rpy="0.0 0.0 0.0"/>
      <geometry>
        <mesh filename="/home/homa/IsaacStressor/assets/arx5_description/meshes/base_arm.STL"/>
      </geometry>
    </collision>
  </link>
  <link name="link1">
    <inertial>
      <origin xyz="0.00625345254733769 -0.024776724575416 0.0152204909116542" rpy="0.0 0.0 0.0"/>
      <mass value="0.0216291264377367"/>
      <inertia ixx="1.15756471313396e-05" ixy="1.63728784702967e-06" ixz="-2.73767909517805e-06" iyy="9.54605859943272e-06" iyz="3.01605409074901e-06" izz="1.06781021447089e-05"/>
    </inertial>
    <visual>
      <origin xyz="0.0 0.0 0.0" rpy="0.0 0.0 0.0"/>
      <geometry>
        <mesh filename="/home/homa/IsaacStressor/assets/arx5_description/meshes/link1.dae"/>
      </geometry>
      <material name="black"/>
    </visual>
    <collision>
      <origin xyz="0.0 0.0 0.0" rpy="0.0 0.0 0.0"/>
      <geometry>
        <mesh filename="/home/homa/IsaacStressor/assets/arx5_description/meshes/link1.STL"/>
      </geometry>
    </collision>
  </link>
  <joint name="arm_joint1" type="revolute">
    <origin xyz="0.0 0.0 0.058" rpy="0.0 0.0 0.0"/>
    <axis xyz="0.0 0.0 1.0"/>
    <parent link="base_link"/>
    <child link="link1"/>
    <limit effort="100.0" lower="-2.0" upper="2.5" velocity="1000.0"/>
  </joint>
  <link name="link2">
    <inertial>
      <origin xyz="-0.0751817740450955 3.45134309138919e-06 -4.55690287344823e-05" rpy="0.0 0.0 0.0"/>
      <mass value="0.317040634327494"/>
      <inertia ixx="0.000148622978788109" ixy="7.9939701538228e-06" ixz="2.11594522192149e-06" iyy="0.000646291918352959" iyz="-1.99305353242084e-08" izz="0.000613128041834933"/>
    </inertial>
    <visual>
      <origin xyz="0.0 0.0 0.0" rpy="0.0 0.0 0.0"/>
      <geometry>
        <mesh filename="/home/homa/IsaacStressor/assets/arx5_description/meshes/link2.dae"/>
      </geometry>
      <material name="black"/>
    </visual>
    <collision>
      <origin xyz="0.0 0.0 0.0" rpy="0.0 0.0 0.0"/>
      <geometry>
        <mesh filename="/home/homa/IsaacStressor/assets/arx5_description/meshes/link2.STL"/>
      </geometry>
    </collision>
  </link>
  <joint name="arm_joint2" type="revolute">
    <origin xyz="0.025013 0.00060169 0.042" rpy="0.0 0.0 0.0"/>
    <axis xyz="0.0 1.0 0.0"/>
    <parent link="link1"/>
    <child link="link2"/>
    <limit effort="100.0" lower="0.0" upper="3.14" velocity="1000.0"/>
  </joint>
  <link name="link3">
    <inertial>
      <origin xyz="0.0958977122336034 -8.54798924280289e-05 -0.0389029227802006" rpy="0.0 0.0 0.0"/>
      <mass value="0.475179901151789"/>
      <inertia ixx="0.000245797731408424" ixy="-1.18756934981885e-06" ixz="-3.08627546217305e-07" iyy="0.000848596965773723" iyz="2.1655980060709e-07" izz="0.00073290848648715"/>
    </inertial>
    <visual>
      <origin xyz="0.0 0.0 0.0" rpy="0.0 0.0 0.0"/>
      <geometry>
        <mesh filename="/home/homa/IsaacStressor/assets/arx5_description/meshes/link3.dae"/>
      </geometry>
      <material name="white">
        <color rgba="0.752 0.7529 0.7529 1.0"/>
      </material>
    </visual>
    <collision>
      <origin xyz="0.0 0.0 0.0" rpy="0.0 0.0 0.0"/>
      <geometry>
        <mesh filename="/home/homa/IsaacStressor/assets/arx5_description/meshes/link3.STL"/>
      </geometry>
    </collision>
  </link>
  <joint name="arm_joint3" type="revolute">
    <origin xyz="-0.26396 0.0044548 0.0" rpy="-3.1416 0.0 -0.015928"/>
    <axis xyz="0.0 1.0 0.0"/>
    <parent link="link2"/>
    <child link="link3"/>
    <limit effort="100.0" lower="0.0" upper="3.14" velocity="1000.0"/>
  </joint>
  <link name="link4">
    <inertial>
      <origin xyz="0.0591385266744759 0.00278044811499105 -0.0552291926495377" rpy="0.0 0.0 0.0"/>
      <mass value="0.138133633872797"/>
      <inertia ixx="5.6812931750694e-05" ixy="3.18564570369191e-06" ixz="3.31187610383292e-06" iyy="5.56751697137782e-05" iyz="-2.13897740775086e-06" izz="6.42957251144152e-05"/>
    </inertial>
    <visual>
      <origin xyz="0.0 0.0 0.0" rpy="0.0 0.0 0.0"/>
      <geometry>
        <mesh filename="/home/homa/IsaacStressor/assets/arx5_description/meshes/link4.dae"/>
      </geometry>
      <material name="black"/>
    </visual>
    <collision>
      <origin xyz="0.0 0.0 0.0" rpy="0.0 0.0 0.0"/>
      <geometry>
        <mesh filename="/home/homa/IsaacStressor/assets/arx5_description/meshes/link4.STL"/>
      </geometry>
    </collision>
  </link>
  <joint name="arm_joint4" type="revolute">
    <origin xyz="0.246 -0.00025 -0.06" rpy="0.0 0.0 0.0"/>
    <axis xyz="0.0 1.0 0.0"/>
    <parent link="link3"/>
    <child link="link4"/>
    <limit effort="100.0" lower="-1.3" upper="1.3" velocity="1000.0"/>
  </joint>
  <link name="link5">
    <inertial>
      <origin xyz="0.00870303426445659 -2.87406901246252e-05 0.0817957433312705" rpy="0.0 0.0 0.0"/>
      <mass value="0.126741777607625"/>
      <inertia ixx="5.2870226427243e-05" ixy="-3.41758559092594e-08" ixz="1.05281937338646e-06" iyy="4.14245046680039e-05" iyz="-7.47381113966083e-08" izz="4.46265559731496e-05"/>
    </inertial>
    <visual>
      <origin xyz="0.0 0.0 0.0" rpy="0.0 0.0 0.0"/>
      <geometry>
        <mesh filename="/home/homa/IsaacStressor/assets/arx5_description/meshes/link5.dae"/>
      </geometry>
      <material name="black"/>
    </visual>
    <collision>
      <origin xyz="0.0 0.0 0.0" rpy="0.0 0.0 0.0"/>
      <geometry>
        <mesh filename="/home/homa/IsaacStressor/assets/arx5_description/meshes/link5.STL"/>
      </geometry>
    </collision>
  </link>
  <joint name="arm_joint5" type="revolute">
    <origin xyz="0.06775 0.0015 -0.0855" rpy="0.0 0.0 -0.015928"/>
    <axis xyz="0.0 0.0 1.0"/>
    <parent link="link4"/>
    <child link="link5"/>
    <limit effort="100.0" lower="-1.5" upper="1.5" velocity="1000.0"/>
  </joint>
  <joint name="arm_joint6" type="revolute">
    <origin xyz="0.03095 0.0 0.0855" rpy="-3.1416 0.0 0.0"/>
    <axis xyz="1.0 0.0 0.0"/>
    <parent link="link5"/>
    <child link="manipulator_flange"/>
    <limit effort="100.0" lower="-1.9" upper="1.9" velocity="1000.0"/>
  </joint>
  <joint name="manipulator_base_joint" type="fixed">
    <origin xyz="0.0 -0.126 0.0" rpy="0.0 0.0 0.0"/>
    <parent link="world"/>
    <child link="base_link"/>
  </joint>
  <joint name="manipulator_control_tip_joint" type="fixed">
    <origin xyz="0.0 0.0 0.0" rpy="0.0 0.0 0.0"/>
    <parent link="manipulator_flange"/>
    <child link="control_tip"/>
  </joint>
  <link name="control_tip"/>
  <link name="link6">
    <inertial>
      <origin xyz="0.038317562848284 -4.45000434657139e-05 0.00355875192843721" rpy="0.0 0.0 0.0"/>
      <mass value="0.142880100739169"/>
      <inertia ixx="9.84190386012445e-05" ixy="9.90777828593097e-08" ixz="2.38841662850396e-07" iyy="3.95328645641678e-05" iyz="2.8992956673539e-07" izz="8.4711562610471e-05"/>
    </inertial>
    <visual>
      <origin xyz="0.0 0.0 0.0" rpy="0.0 0.0 0.0"/>
      <geometry>
        <mesh filename="/home/homa/IsaacStressor/assets/arx5_description/meshes/link6.dae"/>
      </geometry>
      <material name="black"/>
    </visual>
    <collision>
      <origin xyz="0.0 0.0 0.0" rpy="0.0 0.0 0.0"/>
      <geometry>
        <mesh filename="/home/homa/IsaacStressor/assets/arx5_description/meshes/link6.STL"/>
      </geometry>
    </collision>
  </link>
  <link name="link7">
    <inertial>
      <origin xyz="0.00626222055030923 -0.00713411663149576 -0.00289898514345116" rpy="0.0 0.0 0.0"/>
      <mass value="0.0264779585598598"/>
      <inertia ixx="8.79642526953154e-06" ixy="3.0244685599285e-06" ixz="-5.99353466596085e-07" iyy="1.48519274221679e-05" iyz="1.31550651321036e-07" izz="1.1114142640444e-05"/>
    </inertial>
    <visual>
      <origin xyz="0.0 0.0 0.0" rpy="0.0 0.0 0.0"/>
      <geometry>
        <mesh filename="/home/homa/IsaacStressor/assets/arx5_description/meshes/link7.dae"/>
      </geometry>
      <material name="black"/>
    </visual>
    <collision>
      <origin xyz="0.0 0.0 0.0" rpy="0.0 0.0 0.0"/>
      <geometry>
        <mesh filename="/home/homa/IsaacStressor/assets/arx5_description/meshes/link7.STL"/>
      </geometry>
    </collision>
  </link>
  <joint name="arm_joint7" type="prismatic">
    <origin xyz="0.08457 0.024493 -0.00010349" rpy="0.0 0.0 0.0"/>
    <axis xyz="0.0 1.0 0.0"/>
    <parent link="link6"/>
    <child link="link7"/>
    <limit effort="100.0" lower="0.0" upper="0.04765" velocity="1000.0"/>
  </joint>
  <link name="link8">
    <inertial>
      <origin xyz="0.00626222057480438 0.00713411644936678 0.00145300478837504" rpy="0.0 0.0 0.0"/>
      <mass value="0.0264779581346586"/>
      <inertia ixx="9.01311523396113e-06" ixy="-3.02446856817399e-06" ixz="1.52593574709739e-06" iyy="1.50686174477573e-05" iyz="5.73251417689975e-07" izz="1.11141426397578e-05"/>
    </inertial>
    <visual>
      <origin xyz="0.0 0.0 0.0" rpy="0.0 0.0 0.0"/>
      <geometry>
        <mesh filename="/home/homa/IsaacStressor/assets/arx5_description/meshes/link8.dae"/>
      </geometry>
      <material name="black"/>
    </visual>
    <collision>
      <origin xyz="0.0 0.0 0.0" rpy="0.0 0.0 0.0"/>
      <geometry>
        <mesh filename="/home/homa/IsaacStressor/assets/arx5_description/meshes/link8.STL"/>
      </geometry>
    </collision>
  </link>
  <joint name="arm_joint8" type="prismatic">
    <origin xyz="0.08457 -0.024496 -0.00010354" rpy="0.0 0.0 0.0"/>
    <axis xyz="0.0 -1.0 0.0"/>
    <parent link="link6"/>
    <child link="link8"/>
    <limit effort="100.0" lower="0.0" upper="0.04765" velocity="1000.0"/>
  </joint>
  <joint name="manipulator_flange_joint" type="fixed">
    <origin xyz="0.0 0.0 0.0" rpy="0.0 0.0 0.0"/>
    <parent link="manipulator_flange"/>
    <child link="link6"/>
  </joint>
  <material name="zed_mat">
    <color rgba="0.8 0.8 0.8 0.8"/>
  </material>
  <material name="zedm_mat">
    <color rgba="0.0 0.0 0.0 0.9"/>
  </material>
  <material name="zed2_mat">
    <color rgba="0.25 0.25 0.25 0.99"/>
  </material>
  <material name="zed2i_mat">
    <color rgba="0.25 0.25 0.25 0.99"/>
  </material>
  <material name="zedx_mat">
    <color rgba="0.25 0.25 0.25 0.99"/>
  </material>
  <material name="zedxm_mat">
    <color rgba="0.25 0.25 0.25 0.99"/>
  </material>
  <link name="holder_link">
    <visual>
      <origin xyz="0.0 0.0 0.0" rpy="0.0 0.0 0.0"/>
      <geometry>
        <mesh filename="file:///ros_ws/src/universal_manipulation_stand/holders/meshes/xarm6_realsense_wrist.stl" scale="0.001 0.001 0.001"/>
      </geometry>
      <material name="white">
        <color rgba="1.0 1.0 1.0 1.0"/>
      </material>
    </visual>
    <collision>
      <origin xyz="0.0 0.0 0.0" rpy="0.0 0.0 0.0"/>
      <geometry>
        <mesh filename="file:///ros_ws/src/universal_manipulation_stand/holders/meshes/xarm6_realsense_wrist.stl" scale="0.001 0.001 0.001"/>
      </geometry>
    </collision>
  </link>
  <joint name="holder_joint" type="fixed">
    <origin xyz="0.042 0.0 0.0" rpy="-1.57 0.0 -1.57"/>
    <parent link="manipulator_flange"/>
    <child link="holder_link"/>
  </joint>
  <joint name="_joint" type="fixed">
    <origin xyz="0.0 0.74 -0.05" rpy="0.0 0.0 0.0"/>
    <parent link="world"/>
    <child link="_link"/>
  </joint>
  <link name="_link">
    <visual>
      <origin xyz="0.0 0.0 -0.05" rpy="0.0 0.0 0.0"/>
      <geometry>
        <box size="0.88 0.88 0.1"/>
      </geometry>
      <material name="_color">
        <color rgba="1.0 1.0 1.0 1.0"/>
      </material>
    </visual>
    <collision>
      <origin xyz="0.0 0.0 -0.05" rpy="0.0 0.0 0.0"/>
      <geometry>
        <box size="0.88 0.88 0.1"/>
      </geometry>
    </collision>
  </link>
</robot>