<?xml version="1.0"?>

<robot  xmlns:xacro="http://ros.org/wiki/xacro">
  <xacro:macro name="aloha_front_gripper"   params="
   attach_to=''
   prefix=''
   attach_xyz= '0 0 0'
   attach_rpy= '0 0 0'
   " >

        <link name="${prefix}link6">
        <inertial>
            <origin xyz="0.038317562848284 -4.45000434657139E-05 0.00355875192843721" rpy="0 0 0" />
            <mass value="0.142880100739169" />
            <inertia
                ixx="9.84190386012445E-05"
                ixy="9.90777828593097E-08"
                ixz="2.38841662850396E-07"
                iyy="3.95328645641678E-05"
                iyz="2.8992956673539E-07"
                izz="8.4711562610471E-05" />
        </inertial>
        <visual>
            <origin xyz="0 0 0" rpy="0 0 0" />
            <geometry>
                <mesh filename="package://arx5_description/meshes/link6.dae" />
            </geometry>
            <material name="black">

            </material>
        </visual>
        <collision>
            <origin xyz="0 0 0" rpy="0 0 0" />
            <geometry>
                <mesh filename="package://arx5_description/meshes/link6.STL" />
            </geometry>
        </collision>
    </link>
    
    <link name="${prefix}link7">
        <inertial>
            <origin xyz="0.00626222055030923 -0.00713411663149576 -0.00289898514345116" rpy="0 0 0" />
            <mass value="0.0264779585598598" />
            <inertia
                ixx="8.79642526953154E-06"
                ixy="3.0244685599285E-06"
                ixz="-5.99353466596085E-07"
                iyy="1.48519274221679E-05"
                iyz="1.31550651321036E-07"
                izz="1.1114142640444E-05" />
        </inertial>
        <visual>
            <origin xyz="0 0 0" rpy="0 0 0" />
            <geometry>
                <mesh filename="package://arx5_description/meshes/link7.dae" />
            </geometry>
            <material name="black">

            </material>
        </visual>
        <collision>
            <origin xyz="0 0 0" rpy="0 0 0" />
            <geometry>
                <mesh filename="package://arx5_description/meshes/link7.STL" />
            </geometry>
        </collision>
    </link>
    <joint name="${prefix}arm_joint7" type="prismatic">
        <origin xyz="0.08457 0.024493 -0.00010349" rpy="0 0 0" />
        <parent link="${prefix}link6" />
        <child link="${prefix}link7" />
        <axis xyz="0 1 0" />
        <limit lower="0" upper="0.04765" effort="100" velocity="1000" />
    </joint>
    <link name="${prefix}link8">
        <inertial>
            <origin xyz="0.00626222057480438 0.00713411644936678 0.00145300478837504" rpy="0 0 0" />
            <mass value="0.0264779581346586" />
            <inertia
                ixx="9.01311523396113E-06"
                ixy="-3.02446856817399E-06"
                ixz="1.52593574709739E-06"
                iyy="1.50686174477573E-05"
                iyz="5.73251417689975E-07"
                izz="1.11141426397578E-05" />
        </inertial>
        <visual>
            <origin xyz="0 0 0" rpy="0 0 0" />
            <geometry>
                <mesh filename="package://arx5_description/meshes/link8.dae" />
            </geometry>
            <material name="black">

            </material>
        </visual>
        <collision>
        <origin xyz="0 0 0" rpy="0 0 0" />
        <geometry>
            <mesh filename="package://arx5_description/meshes/link8.STL" />
        </geometry>
        </collision>
    </link>
    <joint name="${prefix}arm_joint8" type="prismatic">
        <origin xyz="0.08457 -0.024496 -0.00010354" rpy="0 0 0" />
        <parent link="${prefix}link6" />
        <child link="${prefix}link8" />
        <axis xyz="0 -1 0" />
        <limit lower="0" upper="0.04765" effort="100" velocity="1000" />
    </joint>

    <joint name="${prefix}manipulator_flange_joint" type="fixed">
          <parent link="${attach_to}" />
          <child link="${prefix}link6" />
          <origin xyz="0 0 0" rpy="0 0 0" />
    </joint>
  
</xacro:macro>
</robot>