<?xml version="1.0"?>
<!-- <xacro:include filename="$(find arx5)/urdf/transmission.xacro"/> -->

<robot  xmlns:xacro="http://ros.org/wiki/xacro">
  <xacro:macro name="arx5_robot"   params="
   prefix=''
   attach_xyz=''
   attach_rpy=''
   gripper_flange=''
   " >

    <!--***************************** front-left ****************************** -->
    <link name="${prefix}base_link">
        <inertial>
            <origin xyz="-3.77960552443097E-05 6.79413834922362E-05 0.0272675975957773" rpy="0 0 0" />
            <mass value="0.155112526591278" />
            <inertia ixx="7.60347373757683E-05" ixy="1.31363578468253E-07" ixz="1.65990805634842E-07" iyy="7.64176389864096E-05" iyz="-2.98381448658278E-07" izz="6.94914158355665E-05" />
        </inertial>
        <visual>
            <origin xyz="0 0 0" rpy="0 0 0" />
            <geometry>
                <mesh filename="package://arx5_description/meshes/base_arm.dae" />
            </geometry>
            <material name="black">
                <color rgba="0.05 0.05 0.05 0.98" />
            </material>
        </visual>
        <collision>
            <origin xyz="0 0 0" rpy="0 0 0" />
            <geometry>
                <mesh filename="package://arx5_description/meshes/base_arm.STL" />
            </geometry>
        </collision>
    </link>
    
    <link name="${prefix}link1">
        <inertial>
            <origin xyz="0.00625345254733769 -0.024776724575416 0.0152204909116542" rpy="0 0 0" />
            <mass value="0.0216291264377367" />
            <inertia
                ixx="1.15756471313396E-05"
                ixy="1.63728784702967E-06"
                ixz="-2.73767909517805E-06"
                iyy="9.54605859943272E-06"
                iyz="3.01605409074901E-06"
                izz="1.06781021447089E-05" />
        </inertial>
        <visual>
            <origin xyz="0 0 0" rpy="0 0 0" />
            <geometry>
                <mesh filename="package://arx5_description/meshes/link1.dae" />
            </geometry>
            <material name="black">

            </material>
        </visual>
        <collision>
            <origin xyz="0 0 0" rpy="0 0 0" />
            <geometry>
                <mesh filename="package://arx5_description/meshes/link1.STL" />
            </geometry>
        </collision>
    </link>
    <joint name="${prefix}arm_joint1" type="revolute">
        <origin xyz="0 0 0.058" rpy="0 0 0" />
        <parent link="${prefix}base_link" />
        <child link="${prefix}link1" />
        <axis xyz="0 0 1" />
        <limit lower="-2" upper="2.5" effort="100" velocity="1000"/>
    </joint>
    <link name="${prefix}link2">
        <inertial>
            <origin xyz="-0.0751817740450955 3.45134309138919E-06 -4.55690287344823E-05" rpy="0 0 0" />
            <mass value="0.317040634327494" />
            <inertia
                ixx="0.000148622978788109"
                ixy="7.9939701538228E-06"
                ixz="2.11594522192149E-06"
                iyy="0.000646291918352959"
                iyz="-1.99305353242084E-08"
                izz="0.000613128041834933" />
        </inertial>
        <visual>
            <origin xyz="0 0 0" rpy="0 0 0" />
            <geometry>
                <mesh filename="package://arx5_description/meshes/link2.dae" />
            </geometry>
            <material name="black">
                
            </material>
        </visual>
        <collision>
        <origin  xyz="0 0 0" rpy="0 0 0" />
        <geometry>
            <mesh filename="package://arx5_description/meshes/link2.STL" />
        </geometry>
        </collision>
    </link>
    <joint name="${prefix}arm_joint2" type="revolute">
        <origin xyz="0.025013 0.00060169 0.042" rpy="0 0 0" />
        <parent link="${prefix}link1" />
        <child link="${prefix}link2" />
        <axis xyz="0 1 0" />
        <limit lower="0" upper="3.14" effort="100" velocity="1000"/>
    </joint>
    <link name="${prefix}link3">
        <inertial>
            <origin xyz="0.0958977122336034 -8.54798924280289E-05 -0.0389029227802006" rpy="0 0 0" />
            <mass value="0.475179901151789" />
            <inertia
                ixx="0.000245797731408424"
                ixy="-1.18756934981885E-06"
                ixz="-3.08627546217305E-07"
                iyy="0.000848596965773723"
                iyz="2.1655980060709E-07"
                izz="0.00073290848648715" />
        </inertial>
        <visual>
            <origin xyz="0 0 0" rpy="0 0 0" />
            <geometry>
                <mesh filename="package://arx5_description/meshes/link3.dae" />
            </geometry>
            <material name="white">
                <color rgba="0.752 0.7529 0.7529 1" />
            </material>
        </visual>
        <collision>
            <origin xyz="0 0 0" rpy="0 0 0" />
            <geometry>
                <mesh filename="package://arx5_description/meshes/link3.STL" />
            </geometry>
        </collision>
    </link>
    <joint name="${prefix}arm_joint3" type="revolute">
        <origin xyz="-0.26396 0.0044548 0" rpy="-3.1416 0 -0.015928" />
        <parent link="${prefix}link2" />
        <child link="${prefix}link3" />
        <axis xyz="0 1 0" />
        <limit lower="0" upper="3.14" effort="100" velocity="1000"/>
    </joint>
        <link name="${prefix}link4">
        <inertial>
            <origin xyz="0.0591385266744759 0.00278044811499105 -0.0552291926495377" rpy="0 0 0" />
            <mass value="0.138133633872797" />
            <inertia
                ixx="5.6812931750694E-05"
                ixy="3.18564570369191E-06"
                ixz="3.31187610383292E-06"
                iyy="5.56751697137782E-05"
                iyz="-2.13897740775086E-06"
                izz="6.42957251144152E-05" />
        </inertial>
        <visual>
            <origin xyz="0 0 0" rpy="0 0 0" />
            <geometry>
                <mesh filename="package://arx5_description/meshes/link4.dae" />
            </geometry>
            <material name="black">
            
            </material>
        </visual>
        <collision>
            <origin xyz="0 0 0" rpy="0 0 0" />
            <geometry>
                <mesh filename="package://arx5_description/meshes/link4.STL" />
            </geometry>
        </collision>
    </link>
    <joint name="${prefix}arm_joint4" type="revolute">
        <origin xyz="0.246 -0.00025 -0.06" rpy="0 0 0" />
        <parent link="${prefix}link3" />
        <child link="${prefix}link4" />
        <axis xyz="0 1 0" />
        <limit lower="-1.3" upper="1.3" effort="100" velocity="1000"/>
    </joint>
        <link name="${prefix}link5">
        <inertial>
            <origin xyz="0.00870303426445659 -2.87406901246252E-05 0.0817957433312705" rpy="0 0 0" />
            <mass value="0.126741777607625" />
            <inertia
                ixx="5.2870226427243E-05"
                ixy="-3.41758559092594E-08"
                ixz="1.05281937338646E-06"
                iyy="4.14245046680039E-05"
                iyz="-7.47381113966083E-08"
                izz="4.46265559731496E-05" />
        </inertial>
        <visual>
            <origin xyz="0 0 0" rpy="0 0 0" />
            <geometry>
                <mesh filename="package://arx5_description/meshes/link5.dae" />
            </geometry>
            <material name="black">

            </material>
        </visual>
        <collision>
            <origin xyz="0 0 0" rpy="0 0 0" />
            <geometry>
                <mesh filename="package://arx5_description/meshes/link5.STL" />
            </geometry>
        </collision>
    </link>
    <joint name="${prefix}arm_joint5" type="revolute">
        <origin xyz="0.06775 0.0015 -0.0855" rpy="0 0 -0.015928" />
        <parent link="${prefix}link4" />
        <child link="${prefix}link5" />
        <axis xyz="0 0 1" />
        <limit lower="-1.5" upper="1.5" effort="100" velocity="1000"/>
    </joint>


    <joint name="${prefix}arm_joint6" type="revolute">
        <origin xyz="0.03095 0 0.0855" rpy="-3.1416 0 0" />
        <parent link="${prefix}link5" />
        <child link="${gripper_flange}" />
        <axis xyz="1 0 0" />
        <limit lower="-1.9" upper="1.9" effort="100" velocity="1000"/>
    </joint>

</xacro:macro>
</robot>